Workbook

Sheet Sheet1

Sheet SUMMARY
D1: PROJECT:
D2: ADDRESS:
D3: DATE
B5: TOTAL BUILDING SF
B6: TOTAL NO. OF FLOORS
B7: TOTAL NO. OF BATHS
B8: TOTAL NO. OF KITCHENS
B9: TOTAL NO. OF UNITS (IF ANY) | C9: N/A
B11: COST PER SF
B13: CSI DIV. | C13: DESCRIPTION | D13: TOTAL TRADE COST | E13: REMARKS
B15: DIV.01 | C15: GENERAL CONDITIONS | D15: ='Detailed Estimate '!K7 -> 3500000
A16: =IF(G16<>"",1+MAX($A$1:A15),"") | B16: DIV.03 | C16: CONCRETE | D16: ='Detailed Estimate '!K11 -> 6648198.5
A17: =IF(G17<>"",1+MAX($A$1:A16),"") | B17: DIV.04 | C17: MASONRY | D17: ='Detailed Estimate '!K185 -> 309372.53
A18: =IF(G18<>"",1+MAX($A$1:A17),"") | B18: DIV.05 | C18: METALS | D18: ='Detailed Estimate '!K193 -> 1780083.6
A19: =IF(G19<>"",1+MAX($A$1:A18),"") | B19: DIV.06 | C19: WOOD, PLASTICS & COMPOSITION | D19: ='Detailed Estimate '!K226 -> 3277136.4
A20: =IF(G20<>"",1+MAX($A$1:A19),"") | B20: DIV.07 | C20: THERMAL AND MOISTURE PROTECTION | D20: ='Detailed Estimate '!K248 -> 1134110.6
A21: =IF(G21<>"",1+MAX($A$1:A20),"") | B21: DIV.08 | C21: OPENINGS | D21: ='Detailed Estimate '!K298 -> 4059816.5
A22: =IF(G22<>"",1+MAX($A$1:A21),"") | B22: DIV.09 | C22: FINISHES | D22: ='Detailed Estimate '!K405 -> 5565120.4
A23: =IF(G23<>"",1+MAX($A$1:A22),"") | B23: DIV.10 | C23: SPECIALTIES | D23: ='Detailed Estimate '!K496 -> 419615
A24: =IF(G24<>"",1+MAX($A$1:A23),"") | B24: DIV.11 | C24: EQUIPMENT | D24: ='Detailed Estimate '!K508 -> 955200
A25: =IF(G25<>"",1+MAX($A$1:A24),"") | B25: DIV.12 | C25: FURNISHINGS | D25: ='Detailed Estimate '!K516 -> 399313.86
A26: =IF(G26<>"",1+MAX($A$1:A25),"") | B26: DIV.21 | C26: FIRE PROTECTION | D26: ='Detailed Estimate '!K522 -> 407892.81
A27: =IF(G27<>"",1+MAX($A$1:A26),"") | B27: DIV.22 | C27: PLUMBING | D27: ='Detailed Estimate '!K552 -> 2302746
A28: =IF(G28<>"",1+MAX($A$1:A27),"") | B28: DIV.23 | C28: MECHANICAL | D28: ='Detailed Estimate '!K617 -> 1544425.8
A29: =IF(G29<>"",1+MAX($A$1:A28),"") | B29: DIV.26 | C29: ELECTRICAL | D29: ='Detailed Estimate '!K682 -> 1883820
A30: =IF(G30<>"",1+MAX($A$1:A29),"") | B30: DIV.31 | C30: EARTHWORK | D30: ='Detailed Estimate '!K743 -> 851461.31
A31: =IF(G31<>"",1+MAX($A$1:A30),"")
C32: SUBTOTAL | D32: =SUM(D15:D30) -> 35038313
C33: OVERHEAD & PROFIT - 25% | D33: =0.25*D32 -> 8759578.3
C34: TOTAL BID | D34: =SUM(D32:D33) -> 43797892
A36: =IF(G49<>"",1+MAX($A$1:A35),"") | C36: EXCLUSIONS
A37: =IF(G50<>"",1+MAX($A$1:A36),"") | C37: ALL ITEMS NOT MENTIONED ABOVE ARE EXCLUDED
A38: =IF(G51<>"",1+MAX($A$1:A37),"")
A39: =IF(G52<>"",1+MAX($A$1:A38),"")
A40: =IF(G53<>"",1+MAX($A$1:A39),"")
A41: =IF(G54<>"",1+MAX($A$1:A40),"")
A42: =IF(G55<>"",1+MAX($A$1:A41),"")
A43: =IF(G56<>"",1+MAX($A$1:A42),"")
A44: =IF(G57<>"",1+MAX($A$1:A43),"")
A45: =IF(G58<>"",1+MAX($A$1:A44),"")
...

Sheet Detailed Estimate 
G1: PROJECT:
G2: ADDRESS:
G3: DATE
A5: SR # | B5: DRAWING# | C5: CSI SECT | D5: DESCRIPTION | E5: QTY. | F5: WASTAGE | G5: QTY WITH WASTAGE | H5: UNIT OF MEASURMENT | I5: UNIT COST | J5: TOTAL ITEM COST | K5: TOTAL TRADE COST
A7: =IF(H7<>"",1+MAX(#REF!),"") | C7: DIV. 01 | D7: GENERAL CONDITIONS | K7: =SUM(J8:J10) -> 3500000
A8: =IF(H8<>"",1+MAX($A$1:A7),"")
A9: =IF(H9<>"",1+MAX($A$1:A8),"") -> 1 | D9: PERMITS, SITE SUPERVISION, FINAL CLEANUP, INSURANCE ETC. | E9: 1 | F9: 0 | G9: =E9*(1+F9) -> 1 | H9: LS | I9: 3500000 | J9: =I9*G9 -> 3500000
A10: =IF(H10<>"",1+MAX($A$1:A9),"")
B11: DIV. 03 | D11: CONCRETE | K11: =SUM(J12:J184) -> 6648198.5
D13: FOOTING
A14: =IF(H14<>"",1+MAX($A$1:A13),"")
A15: =IF(H15<>"",1+MAX($A$1:A14),"") | D15: SQUARE FOOTING
A16: =IF(H16<>"",1+MAX($A$1:A15),"") -> 2 | B16: FO-100, FO-200 | D16: 3F6.5: 6'-6" x 6'-6" x 2'-6"D FOOTING W/5#11 AT BOTTOM EW NO. OF FOOTINGS= 1 | E16: =6.5*6.5*2.5/27 -> 3.912037 | F16: 0.1 | G16: =E16*(1+F16) -> 4.3032407 | H16: CY | I16: 800 | J16: =I16*G16 -> 3442.5926
A17: =IF(H17<>"",1+MAX($A$1:A16),"") -> 3 | D17: 3F12.5: 12'-6" x 12'-6" x 3'-0"D FOOTING W/11#11 AT BOTTOM EW NO. OF FOOTINGS= 8 | E17: =12.5*12.5*3/27*8 -> 138.88889 | F17: 0.1 | G17: =E17*(1+F17) -> 152.77778 | H17: CY | I17: 800 | J17: =I17*G17 -> 122222.22
A18: =IF(H18<>"",1+MAX($A$1:A17),"") -> 4 | D18: 3F14.5: 14'-6" x 14'-6" x 3'-6"D FOOTING W/15#11 AT BOTTOM EW NO. OF FOOTINGS= 5 | E18: =14.5*14.5*3.5/27*5 -> 136.27315 | F18: 0.1 | G18: =E18*(1+F18) -> 149.90046 | H18: CY | I18: 800 | J18: =I18*G18 -> 119920.37
A19: =IF(H19<>"",1+MAX($A$1:A18),"") -> 5 | D19: 3F15.5: 15'-6" x 15'-6" x 4'-0"D FOOTING W/16#11 AT BOTTOM EW NO. OF FOOTINGS= 1 | E19: =15.5*15.5*4/27 -> 35.592593 | F19: 0.1 | G19: =E19*(1+F19) -> 39.151852 | H19: CY | I19: 800 | J19: =I19*G19 -> 31321.481
A20: =IF(H20<>"",1+MAX($A$1:A19),"")
A21: =IF(H21<>"",1+MAX($A$1:A20),"") | D21: RECTANGULAR FOOTING
A22: =IF(H22<>"",1+MAX($A$1:A21),"") -> 6 | B22: FO-100, FO-200 | D22: 3F12x5: 12'-0" x 5'-0" x 2'-6"D FOOTING W/5#11 LONG & 10#9 SHORT BARS NO. OF FOOTINGS= 4 | E22: =12*5*2.5/27*4 -> 22.222222 | F22: 0.1 | G22: =E22*(1+F22) -> 24.444444 | H22: CY | I22: 800 | J22: =I22*G22 -> 19555.556
A23: =IF(H23<>"",1+MAX($A$1:A22),"") -> 7 | D23: 3F14x12: 14'-0" x 12'-0" x 3'-2"D FOOTING W/12#11 LONG & 11#11 SHORT BARS NO. OF FOOTINGS= 1 | E23: =14*12*3.17/27 -> 19.724444 | F23: 0.1 | G23: =E23*(1+F23) -> 21.696889 | H23: CY | I23: 800 | J23: =I23*G23 -> 17357.511
A24: =IF(H24<>"",1+MAX($A$1:A23),"") -> 8 | D24: 3F12.5x22: 12'-6" x 22'-0" x 4'-0"D FOOTING W/22#10 LONG & 18#11 SHORT BARS NO. OF FOOTINGS= 1 | E24: =12.5*22*4/27 -> 40.740741 | F24: 0.1 | G24: =E24*(1+F24) -> 44.814815 | H24: CY | I24: 800 | J24: =I24*G24 -> 35851.852
A25: =IF(H25<>"",1+MAX($A$1:A24),"") -> 9 | D25: 3F16x18: 16'-0" x 18'-0" x 4'-0"D FOOTING W/20#11 LONG & 20#11 SHORT BARS NO. OF FOOTINGS= 1 | E25: =16*18*4/27 -> 42.666667 | F25: 0.1 | G25: =E25*(1+F25) -> 46.933333 | H25: CY | I25: 800 | J25: =I25*G25 -> 37546.667
A26: =IF(H26<>"",1+MAX($A$1:A25),"")
A27: =IF(H27<>"",1+MAX($A$1:A26),"") | D27: MATT
A28: =IF(H28<>"",1+MAX($A$1:A27),"") -> 10 | B28: FO-100, FO-204, FO-205 | D28: 36" MAT FOUNDATION | E28: 205 | F28: 0.1 | G28: =E28*(1+F28) -> 225.5 | H28: CY | I28: 800 | J28: =I28*G28 -> 180400
A29: =IF(H29<>"",1+MAX($A$1:A28),"") -> 11 | D29: 42" MAT FOUNDATION | E29: 492 | F29: 0.1 | G29: =E29*(1+F29) -> 541.2 | H29: CY | I29: 800 | J29: =I29*G29 -> 432960
A30: =IF(H30<>"",1+MAX($A$1:A29),"") -> 12 | D30: 48" MAT FOUNDATION | E30: 677 | F30: 0.1 | G30: =E30*(1+F30) -> 744.7 | H30: CY | I30: 800 | J30: =I30*G30 -> 595760
A31: =IF(H31<>"",1+MAX($A$1:A30),"")
A32: =IF(H32<>"",1+MAX($A$1:A31),"") | D32: SLAB
A33: =IF(H33<>"",1+MAX($A$1:A32),"") -> 13 | B33: FO-100, FO-200, A210 | D33: 5" SLAB ON GRADE W/W.W.F., 2#5 CONTINOUS BARS & 6" GRAVEL BASE | E33: 23951 | F33: 0.1 | G33: =E33*(1+F33) -> 26346.1 | H33: SF | I33: 7.8 | J33: =I33*G33 -> 205499.58
A34: =IF(H34<>"",1+MAX($A$1:A33),"") -> 14 | D34: 8" THK. SLAB W/REINFORCEMENT | E34: =4*485.63 -> 1942.52 | F34: 0.1 | G34: =E34*(1+F34) -> 2136.772 | H34: SF | I34: 7.8 | J34: =I34*G34 -> 16666.822
A35: =IF(H35<>"",1+MAX($A$1:A34),"") -> 15 | D35: 9" THK. SLAB W/REINFORCEMENT | E35: =4*22747.86 -> 90991.44 | F35: 0.1 | G35: =E35*(1+F35) -> 100090.58 | H35: SF | I35: 7.8 | J35: =I35*G35 -> 780706.56
A36: =IF(H36<>"",1+MAX($A$1:A35),"") -> 16 | D36: 10" RAMP SLAB W/#5@10" TOP & BOTTOM EACH WAY | E36: =864+343 -> 1207 | F36: 0.1 | G36: =E36*(1+F36) -> 1327.7 | H36: SF | I36: 7.8 | J36: =I36*G36 -> 10356.06
A37: =IF(H37<>"",1+MAX($A$1:A36),"") -> 17 | D37: 10" THK. SLAB W/#4@10 CONT. BOTTOM REINFORCEMENT | E37: 456 | F37: 0.1 | G37: =E37*(1+F37) -> 501.6 | H37: SF | I37: 7.8 | J37: =I37*G37 -> 3912.48
A38: =IF(H38<>"",1+MAX($A$1:A37),"") -> 18 | D38: 11" CONCRETE SLAB W/#4@10 CONTINOUS BOTTOM EACH WAY | E38: =25994.14+272 -> 26266.14 | F38: 0.1 | G38: =E38*(1+F38) -> 28892.754 | H38: SF | I38: 7.8 | J38: =I38*G38 -> 225363.48
A39: =IF(H39<>"",1+MAX($A$1:A38),"") -> 19 | D39: 12" CONCRETE SLAB W/#5@6" T&B EACH WAY | E39: =223+19271+3024+19950.57 -> 42468.57 | F39: 0.1 | G39: =E39*(1+F39) -> 46715.427 | H39: SF | I39: 7.8 | J39: =I39*G39 -> 364380.33
A40: =IF(H40<>"",1+MAX($A$1:A39),"") -> 20 | D40: 12" CONCRETE PIT SLAB W/#4@12" EACH WAY EACH FACE | E40: 305 | F40: 0.1 | G40: =E40*(1+F40) -> 335.5 | H40: SF | I40: 7.8 | J40: =I40*G40 -> 2616.9
A41: =IF(H41<>"",1+MAX($A$1:A40),"") -> 21 | D41: 14"-16" THK. SLAB W/REINFORCEMENT | E41: 3592 | F41: 0.1 | G41: =E41*(1+F41) -> 3951.2 | H41: SF | I41: 7.8 | J41: =I41*G41 -> 30819.36
A42: =IF(H42<>"",1+MAX($A$1:A41),"") -> 22 | D42: 18" CONCRETE SLAB W/#6@6 TOP & BOTTOM EACH WAY | E42: =22574.56+331 -> 22905.56 | F42: 0.1 | G42: =E42*(1+F42) -> 25196.116 | H42: SF | I42: 7.8 | J42: =I42*G42 -> 196529.7
A43: =IF(H43<>"",1+MAX($A$1:A42),"") -> 23 | D43: 18"x18" CAPITAL | E43: =45*1.5*1.5 -> 101.25 | F43: 0.1 | G43: =E43*(1+F43) -> 111.375 | H43: SF | I43: 7.8 | J43: =I43*G43 -> 868.725
...

Sheet Rough
B1: LF | C1: HT | D1: SF | E1: NET SF | F1: NET LF | G1: GYP- THK. TYPE | H1: GYP SIDES | I1: TOTAL GYP | J1: INSULATION
A2: TYPE-1 | B2: 467 | C2: 9.333 | D2: =B2*C2 -> 4358.511 | E2: =D2-0 -> 4358.511 | F2: =E2/C2 -> 467 | G2: 5/8" PAPERLESS | H2: 1 | I2: =E2*H2 -> 4358.511 | J2: 0
A3: TYPE-2 | B3: 571.1 | C3: 9.333 | D3: =B3*C3 -> 5330.0763 | E3: =D3-(23*3*7)-(7*3.75*3.75) -> 4748.6388 | F3: =E3/C3 -> 508.8009 | G3: 5/8" PAPERLESS | H3: 2 | I3: =E3*H3 -> 9497.2776 | J3: =E3 -> 4748.6388
A4: TYPE-2A | B4: 36.9 | C4: 3.5 | D4: =B4*C4 -> 129.15 | E4: =D4-0 -> 129.15 | F4: =E4/C4 -> 36.9 | G4: 5/8" PAPERLESS | H4: 2 | I4: =E4*H4 -> 258.3 | J4: 0
A5: TYPE-5 | B5: 106 | C5: 9.333 | D5: =B5*C5 -> 989.298 | E5: =D5-(3*7*2) -> 947.298 | F5: =E5/C5 -> 101.49984 | G5: 5/8" X TYPE | H5: 4 | I5: =E5*H5 -> 3789.192 | J5: =E5 -> 947.298
I6: =SUM(I2:I4) -> 14114.089 | J6: =SUM(J2:J5) -> 5695.9368

Sheet Sheet2
B1: DP01 DEMO (E) STAIR AND LANDING, PATCH AND REPAIRE ADJACENT WALL. | C1: DEMOLITION
B2: DP02 DEMO (E) WALL, PATCH AND REPAIR ADJACENT AREA.
B3: DP03 DEMO (E) WALL FOR NEW DOOR/ GATE OPENING.
B4: DP04 DEMO (E) WALL ABOVE (N) ADA PARKING STALL AREA TO RECEIVE (N) SLAB, PATCH AND REPAIR ADJACENT AREA.
B5: DP05 DEMO (E) CHAINLINK FENCE.
B6: DP06 DEMO (E) FLOOR SLAB FOR NEW PLUMBING TRENCH AND PIPES, PATCH AND REPAIR ADJACENT AREA.
B7: DP07 DEMO (E) DOOR, INFILL OPENING, PATCH AND REPAIRE ADJACENT WALL.
B8: DP08 DEMO (E) FLOOR SLAB.
B9: DP09 DEMO (E) ABOVE AND BELOW GRADE STRUCTURE AND FOUNDATION ON SITE, SEE GENERAL NOTES FOR DETAILS.
B10: DP11 REMOVER (E) PARKING STRIP FOR RE-STRIPING.
B11: DP22 DEMO (E) PLASTER FENCE WALL AND GATE AT (E) TRANSFORMER.
B12: DP23 DEMO (E) TRANSFORER PAD AND FLOOR SLAB; SEE ELEC. AND ST.DWGS.
B13: DP24 DEMO (E) WOOD FENCE, TYP.
... B16: SP02 REMOVE EXISTING CURB CUT, PATCH AND REPAIR TO MATCH ADJACENT.
B18: EL01 CUSTOM DECORATIVE STEEL SCREEN PANELS W/ VARYING DENSITY PATTERN, PAINTED FINISH - COLOR TBD, SEE SHEET A9.4 FOR MORE INFO. | C18: EXTERIOR FINISHES
B19: EL02 WHITE CORRUGATED METAL RAIN SCREEN, KYNAR FINISH, PERFORATION/PATTERN TBD, SEE SHEET A9.5 FOR MORE INFO.
B20: EL03 VERTICAL STANDING SEAM METAL PANEL SYSTEM RHEINZINK OR PAINTED FACTORY FINISH - COLOR TBD
B21: EL04 WINDOW WITH DECORATIVE METAL PANEL W/ FACTORY FINISH, CONTRASTING COLOR TBD
B22: EL06 WINDOW SYSTEM W/ FACTORY APPLIED KYNAR FINISH, COLOR T.B.D. SEE SHEET A9.3 FOR MORE INFO.
B23: EL07 MECH. LOUVER INTERGRATED WITH (CURTAIN WALL) WINDOW SYSTEM W/ FACTORY APPLIED KYNAR FINISHE, COLOR TO MATCH WINODW FRAME.
B24: EL08 CANOPY WITIH METAL CLADDING PANEL WITH FACTORY APPLIED FINISH, COLOR: T.B.D. WITH INTERGRATED LIGHTING FIXTURES.
B25: EL09 CONCRETE PARAPET WALL WITH INTERGRATED LIGHTING FIXTURES WHERE OCCURS, SEE ELEC. DRAWING FOR MORE INFO.
B26: EL10 GREEN ROOF/ PLANTER, DRAINAGE AND IRRIGATION SYSTEM RAISED OVER WATERPROOFED CAST IN PLACE CONCRETE SLAB
B27: EL15 PAINTED HOLLOW METAL DOOR, COLOR: T.B.D. SEE SHEET A9.1 FOR MORE INFO.
B28: EL16 GREEN WALL/PUBLIC ART PROJECT
B29: EL17 CUSTOM DECORATIVE STEEL SCREEN PANELS, PAINTED FINISH - COLOR TBD
B30: EL18 ELEVATOR DOORS STAINLESS STEEL ELEVATOR DOORS AND FRAMES
... B37: EL35 BACK LIT METAL BUILDING SIGNAGE.
B39: EP02 DECORATIVE ALUMINUM SCREEN WALL WITH FACTORY APPLIED FINISH. COLOR: T.B.D. SEE A9.4 FOR PAN EL SCHEDULE | C39: MISC
B40: EP06 COMBINATION PIPE GUARDRAIL WITH 36" HIGH HANDRAIL. END OF HANDRAIL EXTENSIONRETURN TO GUARD
B41: EP07 GLASS GUARDRAIL
B42: EP09 36" HIGH PIPE HANDRAIL, WALLMOUNTED
