Workbook

Sheet SUMMARY
C1: SCOPE : | D1: ='BASE BID'!D1 -> Plumbing
C2: PROJECT LOCATION : | D2: ='BASE BID'!D2 -> Lewisville Resturant, 2000 FM 544, Lewisvilee TX 75056
C3: DATE SUBMITTED : | D3: ='BASE BID'!D3 -> 46071
C4: PROJECT TYPE: | D4: ='BASE BID'!D4 -> Commercial
C5: REVISION NO.: | D5: ='BASE BID'!D5 -> 00
A7: ITEM # | B7: CSI DIV. | C7: DESCRIPTION | M7: TOTAL LABOR COST | N7: TOTAL MATERIAL COST | O7: TRADE COST
A8: =IF(G8<>"",1+MAX(#REF!),"") | B8: =VLOOKUP($C8,$C$38:$D$61,2,0) -> 01 00 | C8: GENERAL REQUIREMENTS | M8: =SUM('BASE BID'!K10:K16) -> 15000 | N8: =SUM('BASE BID'!M10:M16) -> 0 | O8: =M8+N8 -> 15000
B9: =VLOOKUP($C9,$C$38:$D$61,2,0) -> 22 00 | C9: PLUMBING | M9: =SUM('BASE BID'!K21:K133) -> 48735.792 | N9: =SUM('BASE BID'!M135) -> 110451.78 | O9: =M9+N9 -> 159187.58
A10: SUB TOTAL | M10: =SUM(M8:M9) -> 63735.792 | N10: =SUM(N8:N9) -> 110451.78 | O10: =SUM(O8:O9) -> 174187.58
A11: MATERIAL TAX | D11: 0.0825 | M11: 0 | N11: =D11*N10 -> 9112.2722 | O11: =M11+N11 -> 9112.2722
A12: OVERHEAD & PROFIT / INFLATION (Material) | D12: 0.1 | M12: 0 | N12: =D12*N10 -> 11045.178 | O12: =M12+N12 -> 11045.178
A13: OVERHEAD & PROFIT (Labor) | D13: 0.15 | M13: =M10*D13 -> 9560.3688 | N13: 0 | O13: =M13+N13 -> 9560.3688
A14: CASH ALLOWANCE | M14: 0 | N14: 0 | O14: 0
A15: BOND FEE | D15: 0.015 | O15: =D15*SUM(O10:O14) -> 3058.5809
A16: TOTAL BASE BID | O16: =SUM(O10:O15) -> 206963.98
B18: Note
A19: 1 | C19: Riser Pipe Diagram not given scale so we assumed the scale.
A20: 2 | C20: Lochinvar Sled Furnished By owner PC Responsible For Plumbing Connection To Sled Including Boiler Venting, Boiler Gas Connection Boiler Condensate Drainage, Boiler System Domestic Cold Water Connection And Domestic Hot Water
A21: 3
M23: Legend
M24: DIV. = Division
M25: F.C = Waste or diff. factor
M26: D.O. = Daily Output
B27: Exclusions | M27: LBR. HR. = Labor Hours
A28: 1 | C28: Union Wages. | M28: SF = Square Feet
A29: 2 | C29: Any work not mentioned above. | M29: LF = Linear Feet
A30: 3 | C30: Building Charges (if any). | M30: EA = Each
A31: 4 | C31: Security fee (if any). | M31: CY = Cubic Yard
M32: SY = Fquare Yard
M33: loc = location
M34: LS = lump sum
M35: LBS = Pounds
C38: GENERAL REQUIREMENTS | D38: 01 00
C39: SITE CONDITIONS | D39: 02 00
C40: CONCRETE | D40: 03 00
C41: MASONRY | D41: 04 00
C42: METAL | D42: 05 00
C43: WOOD, PLASTICS & COMPOSITES | D43: 06 00
C44: WATERPROOFING | D44: 07 00
C45: OPENNINGS | D45: 08 00
...

Sheet BASE BID
C1: SCOPE : | D1: Plumbing
C2: PROJECT LOCATION : | D2: Lewisville Resturant, 2000 FM 544, Lewisvilee TX 75056
C3: DATE SUBMITTED : | D3: 46071
C4: PROJECT TYPE: | D4: Commercial
C5: REVISION NO.: | D5: 00
A7: ITEM # | B7: CSI DIV. | C7: DESCRIPTION | D7: BARE QTY. | E7: WASTAGE | F7: QTY. WITH WASTAGE | G7: UNIT | H7: UNIT LABOR HOURS | I7: TOTAL LABOR HOURS | J7: PER HOUR LABOR RATE | K7: TOTAL LABOR COST | L7: UNIT MATERIAL COST | M7: TOTAL MATERIAL COST | N7: ITEM COST | O7: TRADE COST
A8: =IF(G8<>"",1+MAX(#REF!),"") | B8: =VLOOKUP($C8,$C$139:$D$162,2,0) -> 01 00 | C8: GENERAL REQUIREMENTS | O8: =SUM(N9:N17) -> 15000 | P8: =SUM(N20:N134) -> 159187.58
A10: =IF(G10<>"",1+MAX($A$8:A9),"") -> 1 | C10: Plan Design & Permitting | D10: 1 | E10: 0 | F10: =CEILING(SUM(D10:D10)*(1+E10),1) -> 1 | G10: LS | H10: 0 | I10: =F10*H10 -> 0 | J10: 0 | K10: 1700 | M10: =L10*F10 -> 0 | N10: 1700 | P10: 0.0085
A11: =IF(G11<>"",1+MAX($A$8:A10),"") -> 2 | C11: Utilities | D11: 1 | E11: 0 | F11: =CEILING(SUM(D11:D11)*(1+E11),1) -> 1 | G11: LS | H11: 0 | I11: =F11*H11 -> 0 | J11: 0 | K11: 2500 | M11: =L11*F11 -> 0 | N11: 2500 | P11: 0.0075
A12: =IF(G12<>"",1+MAX($A$8:A11),"") -> 3 | C12: Equipment & Tools | D12: 1 | E12: 0 | F12: =CEILING(SUM(D12:D12)*(1+E12),1) -> 1 | G12: LS | H12: 0 | I12: =F12*H12 -> 0 | J12: 0 | K12: 4500 | M12: =L12*F12 -> 0 | N12: 4500 | P12: 0.0095
A13: =IF(G13<>"",1+MAX($A$8:A12),"") -> 4 | C13: Signage & Promotion | D13: 1 | E13: 0 | F13: =CEILING(SUM(D13:D13)*(1+E13),1) -> 1 | G13: LS | H13: 0 | I13: =F13*H13 -> 0 | J13: 0 | K13: 0 | M13: =L13*F13 -> 0 | N13: =K13*F13 -> 0 | P13: 0.0065
A14: =IF(G14<>"",1+MAX($A$8:A13),"") -> 5 | C14: Cleaning & Final | D14: 1 | E14: 0 | F14: =CEILING(SUM(D14:D14)*(1+E14),1) -> 1 | G14: LS | H14: 0 | I14: =F14*H14 -> 0 | J14: 0 | K14: 0 | M14: =L14*F14 -> 0 | N14: =K14*F14 -> 0 | P14: 0.0075
A15: =IF(G15<>"",1+MAX($A$8:A14),"") -> 6 | C15: Bonds, Insurance, Legal | D15: 1 | E15: 0 | F15: =CEILING(SUM(D15:D15)*(1+E15),1) -> 1 | G15: LS | H15: 0 | I15: =F15*H15 -> 0 | J15: 0 | K15: 2800 | M15: =L15*F15 -> 0 | N15: 2800 | P15: 0.015
A16: =IF(G16<>"",1+MAX($A$8:A15),"") -> 7 | C16: Project Management & Supervision | D16: 1 | E16: 0 | F16: =CEILING(SUM(D16:D16)*(1+E16),1) -> 1 | G16: LS | H16: 0 | I16: =F16*H16 -> 0 | J16: 0 | K16: 3500 | M16: =L16*F16 -> 0 | N16: 3500 | P16: 0.035
A17: =IF(G17<>"",1+MAX($A$8:A16),"")
A18: =IF(G18<>"",1+MAX($A$8:A17),"") | B18: =SUMMARY!B9 -> 22 00 | C18: PLUMBING | O18: =SUM(N19:N134) -> 159187.58
A19: =IF(G19<>"",1+MAX($A$8:A18),"")
A20: =IF(G20<>"",1+MAX($A$8:A19),"") | C20: Pipework
A21: =IF(G21<>"",1+MAX($A$8:A20),"") -> 8 | C21: (3" Dia) Vent Pipe | D21: 33.74 | E21: 0.05 | F21: =CEILING(SUM(D21:D21)*(1+E21),1) -> 36 | G21: LF | H21: 0.305 | I21: =H21*F21 -> 10.98 | J21: 48 | K21: =J21*I21 -> 527.04 | L21: 16.25 | M21: =L21*F21 -> 585 | N21: =M21+K21 -> 1112.04
A22: =IF(G22<>"",1+MAX($A$8:A21),"") -> 9 | C22: (2" Dia) Vent Pipe | D22: 484.33 | E22: 0.05 | F22: =CEILING(SUM(D22:D22)*(1+E22),1) -> 509 | G22: LF | H22: 0.25 | I22: =H22*F22 -> 127.25 | J22: 48 | K22: =J22*I22 -> 6108 | L22: 9.15 | M22: =L22*F22 -> 4657.35 | N22: =M22+K22 -> 10765.35
A23: =IF(G23<>"",1+MAX($A$8:A22),"") -> 10 | C23: (5" Dia) Strom Drain Pipe | D23: 153.37 | E23: 0.05 | F23: =CEILING(SUM(D23:D23)*(1+E23),1) -> 162 | G23: LF | H23: 0.45 | I23: =H23*F23 -> 72.9 | J23: 48 | K23: =J23*I23 -> 3499.2 | L23: 26 | M23: =L23*F23 -> 4212 | N23: =M23+K23 -> 7711.2
A24: =IF(G24<>"",1+MAX($A$8:A23),"") -> 11 | C24: (4" Dia) Grease Waste Pipe | D24: 93.69 | E24: 0.05 | F24: =CEILING(SUM(D24:D24)*(1+E24),1) -> 99 | G24: LF | H24: 0.41 | I24: =H24*F24 -> 40.59 | J24: 48 | K24: =J24*I24 -> 1948.32 | L24: 21.5 | M24: =L24*F24 -> 2128.5 | N24: =M24+K24 -> 4076.82
A25: =IF(G25<>"",1+MAX($A$8:A24),"") -> 12 | C25: (3" Dia) Grease Waste Pipe | D25: 217.93 | E25: 0.05 | F25: =CEILING(SUM(D25:D25)*(1+E25),1) -> 229 | G25: LF | H25: 0.305 | I25: =H25*F25 -> 69.845 | J25: 48 | K25: =J25*I25 -> 3352.56 | L25: 16.25 | M25: =L25*F25 -> 3721.25 | N25: =M25+K25 -> 7073.81
A26: =IF(G26<>"",1+MAX($A$8:A25),"") -> 13 | C26: (2" Dia) Grease Waste Pipe | D26: 10.18 | E26: 0.05 | F26: =CEILING(SUM(D26:D26)*(1+E26),1) -> 11 | G26: LF | H26: 0.25 | I26: =H26*F26 -> 2.75 | J26: 48 | K26: =J26*I26 -> 132 | L26: 9.15 | M26: =L26*F26 -> 100.65 | N26: =M26+K26 -> 232.65
A27: =IF(G27<>"",1+MAX($A$8:A26),"") -> 14 | C27: (4" Dia) Sanitary Waste Pipe | D27: 60.63 | E27: 0.05 | F27: =CEILING(SUM(D27:D27)*(1+E27),1) -> 64 | G27: LF | H27: 0.33 | I27: =H27*F27 -> 21.12 | J27: 48 | K27: =J27*I27 -> 1013.76 | L27: 21.5 | M27: =L27*F27 -> 1376 | N27: =M27+K27 -> 2389.76
A28: =IF(G28<>"",1+MAX($A$8:A27),"") -> 15 | C28: (3" Dia) Sanitary Waste Pipe | D28: 191.41 | E28: 0.05 | F28: =CEILING(SUM(D28:D28)*(1+E28),1) -> 201 | G28: LF | H28: 0.305 | I28: =H28*F28 -> 61.305 | J28: 48 | K28: =J28*I28 -> 2942.64 | L28: 16.25 | M28: =L28*F28 -> 3266.25 | N28: =M28+K28 -> 6208.89
A29: =IF(G29<>"",1+MAX($A$8:A28),"") -> 16 | C29: (2" Dia) Sanitary Waste Pipe | D29: 69.01 | E29: 0.05 | F29: =CEILING(SUM(D29:D29)*(1+E29),1) -> 73 | G29: LF | H29: 0.25 | I29: =H29*F29 -> 18.25 | J29: 48 | K29: =J29*I29 -> 876 | L29: 9.15 | M29: =L29*F29 -> 667.95 | N29: =M29+K29 -> 1543.95
A30: =IF(G30<>"",1+MAX($A$8:A29),"") -> 17 | C30: (6" Dia) Fire Water Service Pipe | D30: 21.8 | E30: 0.05 | F30: =CEILING(SUM(D30:D30)*(1+E30),1) -> 23 | G30: LF | H30: 0.41 | I30: =H30*F30 -> 9.43 | J30: 48 | K30: =J30*I30 -> 452.64 | L30: 46 | M30: =L30*F30 -> 1058 | N30: =M30+K30 -> 1510.64
A31: =IF(G31<>"",1+MAX($A$8:A30),"") -> 18 | C31: (2" Dia) Cold Water Pipe | D31: 35.77 | E31: 0.05 | F31: =CEILING(SUM(D31:D31)*(1+E31),1) -> 38 | G31: LF | H31: 0.25 | I31: =H31*F31 -> 9.5 | J31: 48 | K31: =J31*I31 -> 456 | L31: 9.15 | M31: =L31*F31 -> 347.7 | N31: =M31+K31 -> 803.7
A32: =IF(G32<>"",1+MAX($A$8:A31),"") -> 19 | C32: (1 1/2" Dia) Cold Water Pipe | D32: 82.23 | E32: 0.05 | F32: =CEILING(SUM(D32:D32)*(1+E32),1) -> 87 | G32: LF | H32: 0.18 | I32: =H32*F32 -> 15.66 | J32: 48 | K32: =J32*I32 -> 751.68 | L32: 8.6 | M32: =L32*F32 -> 748.2 | N32: =M32+K32 -> 1499.88
... A48: =IF(G48<>"",1+MAX($A$8:A47),"") -> 35 | C48: (1 1/2" Dia) Natural Gas Pipe | D48: 84.05 | E48: 0.05 | F48: =CEILING(SUM(D48:D48)*(1+E48),1) -> 89 | G48: LF | H48: 0.18 | I48: =H48*F48 -> 16.02 | J48: 48 | K48: =J48*I48 -> 768.96 | L48: 8.6 | M48: =L48*F48 -> 765.4 | N48: =M48+K48 -> 1534.36
A49: =IF(G49<>"",1+MAX($A$8:A48),"")
A50: =IF(G50<>"",1+MAX($A$8:A49),"") | C50: Pipe Insulation
A51: =IF(G51<>"",1+MAX($A$8:A50),"") -> 36 | C51: Pipe Insulation (Assume) | D51: 2502 | E51: 0.05 | F51: =CEILING(SUM(D51:D51)*(1+E51),1) -> 2628 | G51: LF | H51: 0.028 | I51: =H51*F51 -> 73.584 | J51: 48 | K51: =J51*I51 -> 3532.032 | L51: 2.58 | M51: =L51*F51 -> 6780.24 | N51: =M51+K51 -> 10312.272
A52: =IF(G52<>"",1+MAX($A$8:A51),"")
A53: =IF(G53<>"",1+MAX($A$8:A52),"")
A54: =IF(G54<>"",1+MAX($A$8:A53),"") | C54: Fitting
A55: =IF(G55<>"",1+MAX($A$8:A54),"") -> 37 | C55: (1" Dia) 90 Degree Elbow | D55: 4 | E55: 0 | F55: =CEILING(SUM(D55:D55)*(1+E55),1) -> 4 | G55: EA | H55: 0.8 | I55: =H55*F55 -> 3.2 | J55: 48 | K55: =J55*I55 -> 153.6 | L55: 22 | M55: =L55*F55 -> 88 | N55: =M55+K55 -> 241.6
A56: =IF(G56<>"",1+MAX($A$8:A55),"") -> 38 | C56: (2" Dia) 90 Degree Elbow | D56: 6 | E56: 0 | F56: =CEILING(SUM(D56:D56)*(1+E56),1) -> 6 | G56: EA | H56: 0.8 | I56: =H56*F56 -> 4.8 | J56: 48 | K56: =J56*I56 -> 230.4 | L56: 22 | M56: =L56*F56 -> 132 | N56: =M56+K56 -> 362.4
A57: =IF(G57<>"",1+MAX($A$8:A56),"") -> 39 | C57: (2" Dia) 45 Degree Elbow | D57: 2 | E57: 0 | F57: =CEILING(SUM(D57:D57)*(1+E57),1) -> 2 | G57: EA | H57: 0.8 | I57: =H57*F57 -> 1.6 | J57: 48 | K57: =J57*I57 -> 76.8 | L57: 22 | M57: =L57*F57 -> 44 | N57: =M57+K57 -> 120.8
...
