Workbook

Sheet SUMMARY
C1: SCOPE : | D1: ='BASE BID'!D1 -> HVAC
C2: PROJECT LOCATION : | D2: ='BASE BID'!D2 -> Freebirds World Burrito, 1811 HWY 287 N. STE 100 Mansfield, TX 76063
C3: DATE SUBMITTED : | D3: ='BASE BID'!D3 -> 46129
C4: PROJECT TYPE:
C5: REVISION NO.: | D5: ='BASE BID'!D5 -> 00
A7: ITEM # | B7: CSI DIV. | C7: DESCRIPTION | M7: TOTAL LABOR COST | N7: TOTAL MATERIAL COST | O7: TRADE COST
A8: =IF(G8<>"",1+MAX(#REF!),"") | B8: =VLOOKUP($C8,$C$38:$D$61,2,0) -> 01 00 | C8: GENERAL REQUIREMENTS | M8: =SUM('BASE BID'!K10:K16) -> 0 | N8: =SUM('BASE BID'!M10:M16) -> 0 | O8: ='BASE BID'!O8 -> 16000
B9: =VLOOKUP($C9,$C$38:$D$61,2,0) -> 23 00 | C9: HVAC | M9: =SUM('BASE BID'!K21:K92) -> 8445.857 | N9: ='BASE BID'!M94 -> 42847.93 | O9: =M9+N9 -> 51293.787
A10: SUB TOTAL | M10: =SUM(M8:M9) -> 8445.857 | N10: =SUM(N8:N9) -> 42847.93 | O10: =SUM(O8:O9) -> 67293.787
A11: MATERIAL TAX | D11: 0.0825 | M11: 0 | N11: =D11*N10 -> 3534.9542 | O11: =M11+N11 -> 3534.9542
A12: OVERHEAD & PROFIT / INFLATION (Material) | D12: 0.1 | M12: 0 | N12: =D12*N10 -> 4284.793 | O12: =M12+N12 -> 4284.793
A13: OVERHEAD & PROFIT (Labor) | D13: 0.15 | M13: =M10*D13 -> 1266.8785 | N13: 0 | O13: =M13+N13 -> 1266.8785
A14: CASH ALLOWANCE | M14: 0 | N14: 0 | O14: 0
A15: BOND FEE | D15: 0.015 | O15: =D15*SUM(O10:O14) -> 1145.7062
A16: TOTAL BASE BID | O16: =SUM(O10:O15) -> 77526.119
B18: Note
A19: 1
A20: 2
A21: 3
M23: Legend
M24: DIV. = Division
M25: F.C = Waste or diff. factor
M26: D.O. = Daily Output
B27: Exclusions | M27: LBR. HR. = Labor Hours
A28: 1 | C28: Union Wages. | M28: SF = Square Feet
A29: 2 | C29: Any work not mentioned above. | M29: LF = Linear Feet
A30: 3 | C30: Building Charges (if any). | M30: EA = Each
A31: 4 | C31: Security fee (if any). | M31: CY = Cubic Yard
M32: SY = Fquare Yard
M33: loc = location
M34: LS = lump sum
M35: LBS = Pounds
C38: GENERAL REQUIREMENTS | D38: 01 00
C39: SITE CONDITIONS | D39: 02 00
C40: CONCRETE | D40: 03 00
C41: MASONRY | D41: 04 00
C42: METAL | D42: 05 00
C43: WOOD, PLASTICS & COMPOSITES | D43: 06 00
C44: WATERPROOFING | D44: 07 00
C45: OPENNINGS | D45: 08 00
...

Sheet BASE BID
C1: SCOPE : | D1: HVAC
C2: PROJECT LOCATION : | D2: Freebirds World Burrito, 1811 HWY 287 N. STE 100 Mansfield, TX 76063
C3: DATE SUBMITTED : | D3: 46129
C4: PROJECT TYPE:
C5: REVISION NO.: | D5: 00
A7: ITEM # | B7: CSI DIV. | C7: DESCRIPTION | D7: BARE QTY. | E7: WASTAGE | F7: QTY. WITH WASTAGE | G7: UNIT | H7: UNIT LABOR HOURS | I7: TOTAL LABOR HOURS | J7: PER HOUR LABOR RATE | K7: TOTAL LABOR COST | L7: UNIT MATERIAL COST | M7: TOTAL MATERIAL COST | N7: ITEM COST | O7: TRADE COST
A8: =IF(G8<>"",1+MAX(#REF!),"") | B8: =VLOOKUP($C8,$C$98:$D$121,2,0) -> 01 00 | C8: GENERAL REQUIREMENTS | O8: =SUM(N9:N16) -> 16000 | P8: =SUM(N20:N92) -> 51293.787
A10: =IF(G10<>"",1+MAX($A$8:A9),"") -> 1 | C10: Plan Design & Permitting | D10: 1 | E10: 0 | F10: =CEILING(SUM(D10:D10)*(1+E10),1) -> 1 | G10: LS | H10: 0 | I10: =F10*H10 -> 0 | J10: 0 | K10: 0 | M10: =L10*F10 -> 0 | N10: 2000 | P10: 0.0085
A11: =IF(G11<>"",1+MAX($A$8:A10),"") -> 2 | C11: Utilities | D11: 1 | E11: 0 | F11: =CEILING(SUM(D11:D11)*(1+E11),1) -> 1 | G11: LS | H11: 0 | I11: =F11*H11 -> 0 | J11: 0 | K11: 0 | M11: =L11*F11 -> 0 | N11: 0 | P11: 0.0075
A12: =IF(G12<>"",1+MAX($A$8:A11),"") -> 3 | C12: Equipment & Tools | D12: 1 | E12: 0 | F12: =CEILING(SUM(D12:D12)*(1+E12),1) -> 1 | G12: LS | H12: 0 | I12: =F12*H12 -> 0 | J12: 0 | K12: 0 | M12: =L12*F12 -> 0 | N12: 2500 | P12: 0.0095
A13: =IF(G13<>"",1+MAX($A$8:A12),"") -> 4 | C13: Signage & Promotion | D13: 1 | E13: 0 | F13: =CEILING(SUM(D13:D13)*(1+E13),1) -> 1 | G13: LS | H13: 0 | I13: =F13*H13 -> 0 | J13: 0 | K13: 0 | M13: =L13*F13 -> 0 | N13: 0 | P13: 0.0065
A14: =IF(G14<>"",1+MAX($A$8:A13),"") -> 5 | C14: Cleaning & Final | D14: 1 | E14: 0 | F14: =CEILING(SUM(D14:D14)*(1+E14),1) -> 1 | G14: LS | H14: 0 | I14: =F14*H14 -> 0 | J14: 0 | K14: 0 | M14: =L14*F14 -> 0 | N14: 2000 | P14: 0.0075
A15: =IF(G15<>"",1+MAX($A$8:A14),"") -> 6 | C15: Bonds, Insurance, Legal | D15: 1 | E15: 0 | F15: =CEILING(SUM(D15:D15)*(1+E15),1) -> 1 | G15: LS | H15: 0 | I15: =F15*H15 -> 0 | J15: 0 | K15: 0 | M15: =L15*F15 -> 0 | N15: 0 | P15: 0.015
A16: =IF(G16<>"",1+MAX($A$8:A15),"") -> 7 | C16: Project Management & Supervision | D16: 1 | E16: 0 | F16: =CEILING(SUM(D16:D16)*(1+E16),1) -> 1 | G16: LS | H16: 0 | I16: =F16*H16 -> 0 | J16: 0 | K16: 0 | M16: =L16*F16 -> 0 | N16: 9500 | P16: 0.035
A17: =IF(G17<>"",1+MAX($A$8:A16),"")
A18: =IF(G18<>"",1+MAX($A$8:A17),"") | B18: =SUMMARY!B9 -> 23 00 | C18: HVAC | O18: =SUM(N19:N93) -> 51293.787
A19: =IF(G19<>"",1+MAX($A$8:A18),"")
A20: =IF(G20<>"",1+MAX($A$8:A19),"") | C20: Ductwork
A21: =IF(G21<>"",1+MAX($A$8:A20),"") -> 8 | C21: (6" Dia) Round Ductwork | D21: 2.69 | E21: 0.05 | F21: =CEILING(SUM(D21:D21)*(1+E21),1) -> 3 | G21: LF | H21: 0.0244 | I21: =H21*F21 -> 0.0732 | J21: 70 | K21: =J21*I21 -> 5.124 | L21: 4.18 | M21: =L21*F21 -> 12.54 | N21: =M21+K21 -> 17.664
A22: =IF(G22<>"",1+MAX($A$8:A21),"") -> 9 | C22: (8" Dia) Round Ductwork | D22: 7.8 | E22: 0.05 | F22: =CEILING(SUM(D22:D22)*(1+E22),1) -> 9 | G22: LF | H22: 0.0266 | I22: =H22*F22 -> 0.2394 | J22: 70 | K22: =J22*I22 -> 16.758 | L22: 4.55 | M22: =L22*F22 -> 40.95 | N22: =M22+K22 -> 57.708
A23: =IF(G23<>"",1+MAX($A$8:A22),"") -> 10 | C23: (12" Dia) Round Ductwork | D23: 11.26 | E23: 0.05 | F23: =CEILING(SUM(D23:D23)*(1+E23),1) -> 12 | G23: LF | H23: 0.0322 | I23: =H23*F23 -> 0.3864 | J23: 70 | K23: =J23*I23 -> 27.048 | L23: 5.24 | M23: =L23*F23 -> 62.88 | N23: =M23+K23 -> 89.928
A24: =IF(G24<>"",1+MAX($A$8:A23),"") -> 11 | C24: (14" Dia) Round Ductwork | D24: 10.87 | E24: 0.05 | F24: =CEILING(SUM(D24:D24)*(1+E24),1) -> 12 | G24: LF | H24: 0.0355 | I24: =H24*F24 -> 0.426 | J24: 70 | K24: =J24*I24 -> 29.82 | L24: 5.78 | M24: =L24*F24 -> 69.36 | N24: =M24+K24 -> 99.18
A25: =IF(G25<>"",1+MAX($A$8:A24),"") -> 12 | C25: (20" Dia) Round Ductwork | D25: 36.49 | E25: 0.05 | F25: =CEILING(SUM(D25:D25)*(1+E25),1) -> 39 | G25: LF | H25: 0.0433 | I25: =H25*F25 -> 1.6887 | J25: 70 | K25: =J25*I25 -> 118.209 | L25: 7.24 | M25: =L25*F25 -> 282.36 | N25: =M25+K25 -> 400.569
A26: =IF(G26<>"",1+MAX($A$8:A25),"") -> 13 | C26: (8" Dia) Flexible Ductwork | D26: 5.18 | E26: 0.05 | F26: =CEILING(SUM(D26:D26)*(1+E26),1) -> 6 | G26: LF | H26: 0.0177 | I26: =H26*F26 -> 0.1062 | J26: 70 | K26: =J26*I26 -> 7.434 | L26: 3.88 | M26: =L26*F26 -> 23.28 | N26: =M26+K26 -> 30.714
A27: =IF(G27<>"",1+MAX($A$8:A26),"") -> 14 | C27: (6" Dia) Flexible Ductwork | D27: 1.95 | E27: 0.05 | F27: =CEILING(SUM(D27:D27)*(1+E27),1) -> 3 | G27: LF | H27: 0.0144 | I27: =H27*F27 -> 0.0432 | J27: 70 | K27: =J27*I27 -> 3.024 | L27: 3.44 | M27: =L27*F27 -> 10.32 | N27: =M27+K27 -> 13.344
A28: =IF(G28<>"",1+MAX($A$8:A27),"") -> 15 | C28: (12" Dia) Flexible Ductwork | D28: 13.99 | E28: 0.05 | F28: =CEILING(SUM(D28:D28)*(1+E28),1) -> 15 | G28: LF | H28: 0.0255 | I28: =H28*F28 -> 0.3825 | J28: 70 | K28: =J28*I28 -> 26.775 | L28: 5.88 | M28: =L28*F28 -> 88.2 | N28: =M28+K28 -> 114.975
A29: =IF(G29<>"",1+MAX($A$8:A28),"") -> 16 | C29: (12"x14") Rectangular Ductwork | D29: 45.28 | E29: 0.05 | F29: =CEILING(SUM(D29:D29)*(1+E29),1) -> 48 | G29: LF | H29: 0.0325 | I29: =H29*F29 -> 1.56 | J29: 70 | K29: =J29*I29 -> 109.2 | L29: 12.34 | M29: =L29*F29 -> 592.32 | N29: =M29+K29 -> 701.52
A30: =IF(G30<>"",1+MAX($A$8:A29),"") -> 17 | C30: (10"x6") Rectangular Ductwork | D30: 30.37 | E30: 0.05 | F30: =CEILING(SUM(D30:D30)*(1+E30),1) -> 32 | G30: LF | H30: 0.0288 | I30: =H30*F30 -> 0.9216 | J30: 70 | K30: =J30*I30 -> 64.512 | L30: 7.24 | M30: =L30*F30 -> 231.68 | N30: =M30+K30 -> 296.192
A31: =IF(G31<>"",1+MAX($A$8:A30),"") -> 18 | C31: (10"x8") Rectangular Ductwork | D31: 25.46 | E31: 0.05 | F31: =CEILING(SUM(D31:D31)*(1+E31),1) -> 27 | G31: LF | H31: 0.0295 | I31: =H31*F31 -> 0.7965 | J31: 70 | K31: =J31*I31 -> 55.755 | L31: 7.88 | M31: =L31*F31 -> 212.76 | N31: =M31+K31 -> 268.515
A32: =IF(G32<>"",1+MAX($A$8:A31),"") -> 19 | C32: (16"x8") Rectangular Ductwork | D32: 5.43 | E32: 0.05 | F32: =CEILING(SUM(D32:D32)*(1+E32),1) -> 6 | G32: LF | H32: 0.0315 | I32: =H32*F32 -> 0.189 | J32: 70 | K32: =J32*I32 -> 13.23 | L32: 8.55 | M32: =L32*F32 -> 51.3 | N32: =M32+K32 -> 64.53
... A40: =IF(G40<>"",1+MAX($A$8:A39),"") -> 27 | C40: (18"x12") Rectangular Ductwork | D40: 6.56 | E40: 0.05 | F40: =CEILING(SUM(D40:D40)*(1+E40),1) -> 7 | G40: LF | H40: 0.0344 | I40: =H40*F40 -> 0.2408 | J40: 70 | K40: =J40*I40 -> 16.856 | L40: 16.5 | M40: =L40*F40 -> 115.5 | N40: =M40+K40 -> 132.356
A41: =IF(G41<>"",1+MAX($A$8:A40),"")
A42: =IF(G42<>"",1+MAX($A$8:A41),"") | C42: Fitting
A43: =IF(G43<>"",1+MAX($A$8:A42),"") -> 28 | C43: 16"x8" x 12"x14" Reducer | D43: 1 | E43: 0 | F43: =CEILING(SUM(D43:D43)*(1+E43),1) -> 1 | G43: EA | H43: 0.228 | I43: =H43*F43 -> 0.228 | J43: 70 | K43: =J43*I43 -> 15.96 | L43: 21.8 | M43: =L43*F43 -> 21.8 | N43: =M43+K43 -> 37.76
A44: =IF(G44<>"",1+MAX($A$8:A43),"") -> 29 | C44: 16"x8" x 14"x14" Reducer | D44: 1 | E44: 0 | F44: =CEILING(SUM(D44:D44)*(1+E44),1) -> 1 | G44: EA | H44: 0.276 | I44: =H44*F44 -> 0.276 | J44: 70 | K44: =J44*I44 -> 19.32 | L44: 21.8 | M44: =L44*F44 -> 21.8 | N44: =M44+K44 -> 41.12
A45: =IF(G45<>"",1+MAX($A$8:A44),"") -> 30 | C45: 10"x8" x 10"x6" Reducer | D45: 1 | E45: 0 | F45: =CEILING(SUM(D45:D45)*(1+E45),1) -> 1 | G45: EA | H45: 0.207 | I45: =H45*F45 -> 0.207 | J45: 70 | K45: =J45*I45 -> 14.49 | L45: 17.3 | M45: =L45*F45 -> 17.3 | N45: =M45+K45 -> 31.79
A46: =IF(G46<>"",1+MAX($A$8:A45),"") -> 31 | C46: 18"x14" x 10"x6" Reducer | D46: 1 | E46: 0 | F46: =CEILING(SUM(D46:D46)*(1+E46),1) -> 1 | G46: EA | H46: 0.255 | I46: =H46*F46 -> 0.255 | J46: 70 | K46: =J46*I46 -> 17.85 | L46: 19.25 | M46: =L46*F46 -> 19.25 | N46: =M46+K46 -> 37.1
A47: =IF(G47<>"",1+MAX($A$8:A46),"") -> 32 | C47: 18"x14" x 12"x14" Reducer | D47: 1 | E47: 0 | F47: =CEILING(SUM(D47:D47)*(1+E47),1) -> 1 | G47: EA | H47: 0.318 | I47: =H47*F47 -> 0.318 | J47: 70 | K47: =J47*I47 -> 22.26 | L47: 21.8 | M47: =L47*F47 -> 21.8 | N47: =M47+K47 -> 44.06
A48: =IF(G48<>"",1+MAX($A$8:A47),"") -> 33 | C48: 18"x14" x 14"x14" Reducer | D48: 1 | E48: 0 | F48: =CEILING(SUM(D48:D48)*(1+E48),1) -> 1 | G48: EA | H48: 0.324 | I48: =H48*F48 -> 0.324 | J48: 70 | K48: =J48*I48 -> 22.68 | L48: 23.4 | M48: =L48*F48 -> 23.4 | N48: =M48+K48 -> 46.08
A49: =IF(G49<>"",1+MAX($A$8:A48),"") -> 34 | C49: 12"x14" x 14"x14" Reducer | D49: 1 | E49: 0 | F49: =CEILING(SUM(D49:D49)*(1+E49),1) -> 1 | G49: EA | H49: 0.267 | I49: =H49*F49 -> 0.267 | J49: 70 | K49: =J49*I49 -> 18.69 | L49: 18.28 | M49: =L49*F49 -> 18.28 | N49: =M49+K49 -> 36.97
...
