Workbook

Sheet Summary
B2: SUMMARY
B14: DATE | D14: PROJECT NAME | E14: ='Detailed Estimate Sheet'!J15 -> PROJECT LOCATION
B15: ='Detailed Estimate Sheet'!B16 -> 45708 | D15: ='Detailed Estimate Sheet'!D16 -> Building E Roof Replacement For UPMC Altoona | E15: ='Detailed Estimate Sheet'!J16 -> 0
D16: ='Detailed Estimate Sheet'!D17 -> 0
B18: LINE NO. | C18: CSI DIV. | D18: DESCRIPTION | E18: MATERIAL COST | F18: LABOR COST | G18: TOTAL COST
B20: =IF(G20<>"",1+MAX($B$18:B19),"") -> 1 | C20: ='Detailed Estimate Sheet'!C21 -> DIV. 01 | D20: ='Detailed Estimate Sheet'!D21 -> GENERAL REQUIREMENTS | E20: ='Detailed Estimate Sheet'!H21+('Detailed Estimate Sheet'!H21*('Detailed Estimate Sheet'!$Q$8+'Detailed Estimate Sheet'!$Q$10+'Detailed Estimate Sheet'!$Q$12))+('Detailed Estimate Sheet'!$Q$11*('Detailed Estimate Sheet'!H21+'Detailed Estimate Sheet'!H21*'Detailed Estimate Sheet'!$Q$8+'Detailed Estimate Sheet'!H21*'Detailed Estimate Sheet'!$Q$10)) -> 0 | F20: ='Detailed Estimate Sheet'!O21+('Detailed Estimate Sheet'!O21*('Detailed Estimate Sheet'!$Q$9+'Detailed Estimate Sheet'!$Q$10+'Detailed Estimate Sheet'!$Q$12))+('Detailed Estimate Sheet'!$Q$11*('Detailed Estimate Sheet'!O21+'Detailed Estimate Sheet'!O21*'Detailed Estimate Sheet'!$Q$9+'Detailed Estimate Sheet'!O21*'Detailed Estimate Sheet'!$Q$10)) -> 0 | G20: ='Detailed Estimate Sheet'!R21 -> 0
B21: =IF(G21<>"",1+MAX($B$18:B20),"") -> 2 | C21: ='Detailed Estimate Sheet'!C25 -> DIV. 02 | D21: ='Detailed Estimate Sheet'!D25 -> EXISTING CONDITIONS | E21: ='Detailed Estimate Sheet'!H25+('Detailed Estimate Sheet'!H25*('Detailed Estimate Sheet'!$Q$8+'Detailed Estimate Sheet'!$Q$10+'Detailed Estimate Sheet'!$Q$12))+('Detailed Estimate Sheet'!$Q$11*('Detailed Estimate Sheet'!H25+'Detailed Estimate Sheet'!H25*'Detailed Estimate Sheet'!$Q$8+'Detailed Estimate Sheet'!H25*'Detailed Estimate Sheet'!$Q$10)) -> 0 | F21: ='Detailed Estimate Sheet'!O25+('Detailed Estimate Sheet'!O25*('Detailed Estimate Sheet'!$Q$9+'Detailed Estimate Sheet'!$Q$10+'Detailed Estimate Sheet'!$Q$12))+('Detailed Estimate Sheet'!$Q$11*('Detailed Estimate Sheet'!O25+'Detailed Estimate Sheet'!O25*'Detailed Estimate Sheet'!$Q$9+'Detailed Estimate Sheet'!O25*'Detailed Estimate Sheet'!$Q$10)) -> 0 | G21: ='Detailed Estimate Sheet'!R25 -> 0
B22: =IF(G22<>"",1+MAX($B$18:B21),"") -> 3 | C22: ='Detailed Estimate Sheet'!C41 -> DIV. 07 | D22: ='Detailed Estimate Sheet'!D41 -> THERMAL AND MOISTURE PROTECTION | E22: ='Detailed Estimate Sheet'!H41+('Detailed Estimate Sheet'!H41*('Detailed Estimate Sheet'!$Q$8+'Detailed Estimate Sheet'!$Q$10+'Detailed Estimate Sheet'!$Q$12))+('Detailed Estimate Sheet'!$Q$11*('Detailed Estimate Sheet'!H41+'Detailed Estimate Sheet'!H41*'Detailed Estimate Sheet'!$Q$8+'Detailed Estimate Sheet'!H41*'Detailed Estimate Sheet'!$Q$10)) -> 0 | F22: ='Detailed Estimate Sheet'!O41+('Detailed Estimate Sheet'!O41*('Detailed Estimate Sheet'!$Q$9+'Detailed Estimate Sheet'!$Q$10+'Detailed Estimate Sheet'!$Q$12))+('Detailed Estimate Sheet'!$Q$11*('Detailed Estimate Sheet'!O41+'Detailed Estimate Sheet'!O41*'Detailed Estimate Sheet'!$Q$9+'Detailed Estimate Sheet'!O41*'Detailed Estimate Sheet'!$Q$10)) -> 0 | G22: ='Detailed Estimate Sheet'!R41 -> 0
B24: 12 | D24: TOTAL PROJECT COST | G24: =SUM(G20:G23) -> 0

Sheet Detailed Estimate Sheet
T1: MAT. FAC. | U1: LAB. FAC.
B2: CONSTRUCTION COST ESTIMATE BREAKDOWN | T2: 1 | U2: 1
B3: CONTRACTOR | I3: ADDRESS | T3: 1.016 | U3: 1.773
I5: TOTAL MATERIAL COST | R5: =SUM(I22:I67) -> 0
I6: TOTAL LABOR COST | R6: =SUM(P22:P67) -> 0
I7: SUBTOTAL | R7: =SUM(R5:R6) -> 0
I8: SALES TAX | Q8: 0.08875 | R8: =R5*Q8 -> 0
I9: LABOR BURDEN | Q9: 0.22 | R9: =R6*Q9 -> 0
I10: OVERHEAD & PROFIT | Q10: 0.25 | R10: =R7*Q10 -> 0
I11: BONDING | Q11: 0.02 | R11: =SUM(R7:R10)*Q11 -> 0
I12: CONTINGENCY / WASTAGE | Q12: 0.05 | R12: =R7*Q12 -> 0
I13: PROPOSED PROJECT AMOUNT | R13: =SUM(R7:R12) -> 0
I14: TOTAL MANHOURS | R14: =SUM(K22:K67) -> 0
B15: DATE | D15: PROJECT NAME | E15: SCOPE OF WORK | J15: PROJECT LOCATION
B16: =TODAY() -> 45708 | D16: Building E Roof Replacement For UPMC Altoona | E16: Roof Replacement
B18: LINE NO. | C18: DWG REF./ CSI SEC. | E18: UNIT OF MEASURE | F18: QUANTITY | G18: MATERIAL | J18: LABOR | Q18: LINE TOTAL | R18: TRADE TOTAL W/ S.TAX, O&P
G19: UNIT PRICE | H19: UNIT PRICE | I19: TOTAL COST | J19: UNIT LABOR HOUR | K19: LABOR HOURS | L19: CREW | M19: LABOR RATE | N19: LABOR RATE | O19: UNIT PRICE | P19: TOTAL COST
B20: =IF(F20<>"",1+MAX($B$1:B19),"")
B21: =IF(F21<>"",1+MAX($B$1:B20),"") | C21: DIV. 01 | D21: GENERAL REQUIREMENTS | E21: SUBTOTAL MATERIAL | H21: =SUM(I22:I24) -> 0 | I21: =F21*H21 -> 0 | K21: SUBTOTAL LABOR | O21: =SUM(P22:P24) -> 0 | P21: =F21*O21 -> 0 | Q21: =SUM(Q22:Q24) -> 0 | R21: =(Q21)+(H21*$Q$8)+(O21*$Q$9)+(Q21*$Q$10)+($Q$11*((Q21)+(H21*$Q$8)+(O21*$Q$9)+(Q21*$Q$10)))+(Q21*$Q$12) -> 0
H22: =G22*$T$2 -> 0 | I22: =F22*H22 -> 0 | K22: =F22*J22 -> 0 | N22: =M22*$U$2 -> 0 | O22: =J22*N22 -> 0 | P22: =F22*O22 -> 0 | Q22: =I22+P22 -> 0
B23: =IF(F23<>"",1+MAX($B$22:B22),"") -> 1 | D23: PERMITS, SITE SUPERVISION, FINAL CLEANUP & DUMPSTER | E23: LS | F23: 1 | H23: =G23*$T$2 -> 0 | I23: =F23*H23 -> 0 | K23: =F23*J23 -> 0 | N23: =M23*$U$2 -> 0 | O23: 0 | P23: =F23*O23 -> 0
B24: =IF(F24<>"",1+MAX($B$22:B23),"") | H24: =G24*$T$2 -> 0 | I24: =F24*H24 -> 0 | K24: =F24*J24 -> 0 | N24: =M24*$U$2 -> 0 | O24: =J24*N24 -> 0 | P24: =F24*O24 -> 0 | Q24: =I24+P24 -> 0
B25: =IF(F25<>"",1+MAX($B$22:B24),"") | C25: DIV. 02 | D25: EXISTING CONDITIONS | E25: SUBTOTAL MATERIAL | H25: =SUM(I26:I36) -> 0 | I25: =F25*H25 -> 0 | K25: SUBTOTAL LABOR | O25: =SUM(P26:P39) -> 0 | P25: =F25*O25 -> 0 | Q25: =SUM(Q26:Q39) -> 0 | R25: =(Q25)+(H25*$Q$8)+(O25*$Q$9)+(Q25*$Q$10)+($Q$11*((Q25)+(H25*$Q$8)+(O25*$Q$9)+(Q25*$Q$10)))+(Q25*$Q$12) -> 0
B26: =IF(F26<>"",1+MAX($B$22:B25),"") | H26: =G26*$T$2 -> 0 | I26: =F26*H26 -> 0 | K26: =F26*J26 -> 0 | N26: =M26*$U$2 -> 0 | O26: =J26*N26 -> 0 | P26: =F26*O26 -> 0 | Q26: =I26+P26 -> 0
B27: =IF(F27<>"",1+MAX($B$22:B26),"") | D27: DEMOLITION | H27: =G27*$T$2 -> 0 | I27: =F27*H27 -> 0 | K27: =F27*J27 -> 0 | N27: =M27*$U$2 -> 0 | O27: =J27*N27 -> 0 | P27: =F27*O27 -> 0 | Q27: =I27+P27 -> 0
B28: =IF(F28<>"",1+MAX($B$22:B27),"") -> 2 | C28: AD101 | D28: Existing Sloped Zonolite 'Crickets' Shall Be Completely Removed Down To The Tectum Deck | E28: SF | F28: 3795 | H28: =G28*$T$2 -> 0 | I28: =F28*H28 -> 0 | J28: 0 | K28: =F28*J28 -> 0 | L28: 1 CLAB | M28: 42.1 | N28: 0 | O28: =J28*N28 -> 0 | P28: =F28*O28 -> 0 | Q28: =I28+P28 -> 0
B29: =IF(F29<>"",1+MAX($B$22:B28),"") -> 3 | D29: Existing Tectum Deck Shall Be Swept/Blown Clean Of All Dirt, Water & Debris | E29: SF | F29: 11725 | H29: =G29*$T$2 -> 0 | I29: =F29*H29 -> 0 | J29: 0 | K29: =F29*J29 -> 0 | L29: 1 CLAB | M29: 42.1 | N29: 0 | O29: =J29*N29 -> 0 | P29: =F29*O29 -> 0 | Q29: =I29+P29 -> 0
B30: =IF(F30<>"",1+MAX($B$22:B29),"") -> 4 | D30: Existing Wood Platform & Railings To Be Remove, Salvage & Reinsatll | E30: SF | F30: 65 | H30: =G30*$T$2 -> 0 | I30: =F30*H30 -> 0 | J30: 0 | K30: =F30*J30 -> 0 | L30: 1 CLAB | M30: 42.1 | N30: 0 | O30: =J30*N30 -> 0 | P30: =F30*O30 -> 0 | Q30: =I30+P30 -> 0
B31: =IF(F31<>"",1+MAX($B$22:B30),"") -> 5 | D31: Existing Roof Pavers To Be Remove, Salvage & Reinsatll | E31: SF | F31: 310 | H31: =G31*$T$2 -> 0 | I31: =F31*H31 -> 0 | J31: 0 | K31: =F31*J31 -> 0 | L31: 1 CLAB | M31: 42.1 | N31: 0 | O31: =J31*N31 -> 0 | P31: =F31*O31 -> 0 | Q31: =I31+P31 -> 0
D32: Existing Wood Stairs & Railings To Be Removed | E32: SF | F32: 14 | H32: =G32*$T$2 -> 0 | I32: =F32*H32 -> 0 | J32: 0 | K32: =F32*J32 -> 0 | L32: 1 CLAB | M32: 42.1 | N32: 0 | O32: =J32*N32 -> 0 | P32: =F32*O32 -> 0 | Q32: =I32+P32 -> 0
D33: Existing Roofing Materials To Be Removed | E33: SF | F33: 11725 | H33: =G33*$T$2 -> 0 | I33: =F33*H33 -> 0 | J33: 0 | K33: =F33*J33 -> 0 | L33: 1 CLAB | M33: 42.1 | N33: 0 | O33: =J33*N33 -> 0 | P33: =F33*O33 -> 0 | Q33: =I33+P33 -> 0
D34: Existing Stair To Be Remove & Dispose | E34: SF | F34: 17 | H34: =G34*$T$2 -> 0 | I34: =F34*H34 -> 0 | J34: 0 | K34: =F34*J34 -> 0 | L34: 1 CLAB | M34: 42.1 | N34: 0 | O34: =J34*N34 -> 0 | P34: =F34*O34 -> 0 | Q34: =I34+P34 -> 0
D35: Unfasten & lift Exsiting Low-Profile Exhaust To Allow For Removal Of Existing Roofing System & Installation Of New Roofing System. Reinstall & Fasten Exhaust (Review & coordinate w/ Owner) | E35: EA | F35: 15 | H35: =G35*$T$2 -> 0 | I35: =F35*H35 -> 0 | J35: 0 | K35: =F35*J35 -> 0 | L35: 1 CLAB | M35: 42.1 | N35: 0 | O35: =J35*N35 -> 0 | P35: =F35*O35 -> 0 | Q35: =I35+P35 -> 0
D36: Existing Fascia To Be Removed | E36: LF | F36: 527 | H36: =G36*$T$2 -> 0 | I36: =F36*H36 -> 0 | J36: 0 | K36: =F36*J36 -> 0 | L36: 1 CLAB | M36: 42.1 | N36: 0 | O36: =J36*N36 -> 0 | P36: =F36*O36 -> 0 | Q36: =I36+P36 -> 0
D38: Patch & Repair
C39: AD101 | D39: Patch & Repair Fireproofing & Rated Assemblies Damaged During Demolition | E39: SF | F39: 11725
B40: =IF(F40<>"",1+MAX($B$22:B36),"") | H40: =G40*$T$2 -> 0 | I40: =F40*H40 -> 0 | K40: =F40*J40 -> 0 | N40: =M40*$U$2 -> 0 | O40: =J40*N40 -> 0 | P40: =F40*O40 -> 0 | Q40: =I40+P40 -> 0
B41: =IF(F41<>"",1+MAX($B$22:B40),"") | C41: DIV. 07 | D41: THERMAL AND MOISTURE PROTECTION | E41: SUBTOTAL MATERIAL | H41: =SUM(I42:I66) -> 0 | I41: =F41*H41 -> 0 | K41: SUBTOTAL LABOR | O41: =SUM(P42:P66) -> 0 | P41: =F41*O41 -> 0 | Q41: =SUM(Q42:Q65) -> 0 | R41: =(Q41)+(H41*$Q$8)+(O41*$Q$9)+(Q41*$Q$10)+($Q$11*((Q41)+(H41*$Q$8)+(O41*$Q$9)+(Q41*$Q$10)))+(Q41*$Q$12) -> 0
B42: =IF(F42<>"",1+MAX($B$22:B41),"") | D42: Roofing | H42: =G42*$T$2 -> 0 | I42: =F42*H42 -> 0 | K42: =F42*J42 -> 0 | N42: =M42*$U$2 -> 0 | O42: =J42*N42 -> 0 | P42: =F42*O42 -> 0 | Q42: =I42+P42 -> 0
B43: =IF(F43<>"",1+MAX($B$22:B42),"") -> 6 | C43: A101 | D43: New Fully-Adhered Non-Reinforced Black EPDM Rubber Membrane Roofing | E43: SF | F43: 11723 | H43: 0 | I43: =F43*H43 -> 0 | J43: 0 | K43: 0 | L43: B-2 | M43: 42.5 | N43: 0 | O43: =J43*N43 -> 0 | P43: =F43*O43 -> 0 | Q43: =I43+P43 -> 0
...
